Workbook
Name usd_kzt: 'Параметры'!$C$4
Name discount_rate: 'Параметры'!$C$5
Name vat: 'Параметры'!$C$6
Name salary_edu: 'Параметры'!$C$7
Name salary_dev: 'Параметры'!$C$8
Name payroll_factor: 'Параметры'!$C$9
Name hours_month: 'Параметры'!$C$10
Name methodist_h_before: 'Параметры'!$C$11
Name methodist_h_after: 'Параметры'!$C$12
Name active_weeks: 'Параметры'!$C$13
Name curators: 'Параметры'!$C$14
Name curator_h_week: 'Параметры'!$C$15
Name curator_saving: 'Параметры'!$C$16
Name curator_weeks: 'Параметры'!$C$17
Name lost_cases_year: 'Параметры'!$C$18
Name lost_case_hours: 'Параметры'!$C$19
Name ramp_y1: 'Параметры'!$C$20
Name dev_hours: 'Параметры'!$C$21
Name pm_ba_hours: 'Параметры'!$C$22
Name migration_hours: 'Параметры'!$C$23
Name users_trained: 'Параметры'!$C$24
Name training_h_user: 'Параметры'!$C$25
Name retraining_h_year: 'Параметры'!$C$26
Name support_h_month: 'Параметры'!$C$27
Name vps_month: 'Параметры'!$C$28
Name backup_vps_month: 'Параметры'!$C$29
Name ws_license_usd: 'Параметры'!$C$30
Name sql_2core_usd: 'Параметры'!$C$31
Name sql_packs: 'Параметры'!$C$32
Name b24_month: 'Параметры'!$C$33
Name b24_setup_hours: 'Параметры'!$C$34
Name b24_support_h_month: 'Параметры'!$C$35
Name b24_benefit_share: 'Параметры'!$C$36
Name decommission_hours: 'Параметры'!$C$37
Name b24_decommission_hours: 'Параметры'!$C$38
Name rate_edu: 'Эффект'!$B$3
Name rate_dev: 'Эффект'!$B$4
Name h_methodist: 'Эффект'!$B$5
Name h_curators: 'Эффект'!$B$6
Name h_lost: 'Эффект'!$B$7
Name h_total: 'Эффект'!$B$8
Name annual_benefit: 'Эффект'!$B$9
Name cost_of_delay: 'Эффект'!$B$10
Name df_row: 'TCO'!$C$4:$F$4

Sheet Сводка
A1: Сводка: TCO, ROI, NPV и окупаемость за 3 года (базовый сценарий)
A3: Вариант | B3: TCO 3 года, ₸ | C3: Выгода 3 года, ₸ | D3: ROI | E3: NPV, ₸ | F3: Окупаемость, лет эксплуатации
A4: В0. Ничего не делать (Excel + почта) | B4: =TCO!G7 | C4: =TCO!G8 | D4: =IF(B4=0,"—",(C4-B4)/B4) | E4: =SUMPRODUCT(TCO!C9:F9,df_row) | F4: =IF(B4=0,"—",IF(TCO!D10>=0,-TCO!C10/TCO!D9,IF(TCO!E10>=0,1-TCO!D10/TCO!E9,IF(TCO!F10>=0,2-TCO!E10/TCO!F9,"не окупается за 3 года"))))
A5: В1. Купить готовое: Битрикс24 «Стандартный» | B5: =TCO!G19 | C5: =TCO!G20 | D5: =IF(B5=0,"—",(C5-B5)/B5) | E5: =SUMPRODUCT(TCO!C21:F21,df_row) | F5: =IF(B5=0,"—",IF(TCO!D22>=0,-TCO!C22/TCO!D21,IF(TCO!E22>=0,1-TCO!D22/TCO!E21,IF(TCO!F22>=0,2-TCO!E22/TCO!F21,"не окупается за 3 года"))))
A6: В2. Своя разработка, проприетарный стек (Windows Server + SQL Server) | B6: =TCO!G32 | C6: =TCO!G33 | D6: =IF(B6=0,"—",(C6-B6)/B6) | E6: =SUMPRODUCT(TCO!C34:F34,df_row) | F6: =IF(B6=0,"—",IF(TCO!D35>=0,-TCO!C35/TCO!D34,IF(TCO!E35>=0,1-TCO!D35/TCO!E34,IF(TCO!F35>=0,2-TCO!E35/TCO!F34,"не окупается за 3 года"))))
A7: В3. Своя разработка, открытый стек (Linux + PostgreSQL + Python) | B7: =TCO!G44 | C7: =TCO!G45 | D7: =IF(B7=0,"—",(C7-B7)/B7) | E7: =SUMPRODUCT(TCO!C46:F46,df_row) | F7: =IF(B7=0,"—",IF(TCO!D47>=0,-TCO!C47/TCO!D46,IF(TCO!E47>=0,1-TCO!D47/TCO!E46,IF(TCO!F47>=0,2-TCO!E47/TCO!F46,"не окупается за 3 года"))))
A8: В3-С. Открытый стек силами студенческой команды (рекомендуется) | B8: =TCO!G56 | C8: =TCO!G57 | D8: =IF(B8=0,"—",(C8-B8)/B8) | E8: =SUMPRODUCT(TCO!C58:F58,df_row) | F8: =IF(B8=0,"—",IF(TCO!D59>=0,-TCO!C59/TCO!D58,IF(TCO!E59>=0,1-TCO!D59/TCO!E58,IF(TCO!F59>=0,2-TCO!E59/TCO!F58,"не окупается за 3 года"))))
A10: Формулы: ROI = (Σ выгод − Σ затрат) / Σ затрат; NPV = Σ (выгода_t − затраты_t) / (1 + r)^t, r = discount_rate;
A11: окупаемость — момент, когда накопленный поток становится ≥ 0 (линейная интерполяция внутри года).
A13: Открытое ПО против проприетарного (В3 против В2)
A14: Разница TCO за 3 года, ₸ | B14: =B6-B7
A15: из них лицензии Windows Server + SQL Server (с НДС), ₸ | B15: =(ws_license_usd+sql_2core_usd*sql_packs)*usd_kzt*(1+vat)
A16: Во сколько раз лицензии больше годового эффекта | B16: =B15/annual_benefit

Sheet Чувствительность
A1: Анализ чувствительности: затраты × k_c, выгода × k_b (жёлтые ячейки можно менять)
B2: База | D2: Затраты +30 % | F2: Эффект 50 % | H2: Затраты +30 % и эффект 50 %
A3: k_c — множитель затрат | B3: 1 | D3: 1.3 | F3: 1 | H3: 1.3
A4: k_b — множитель выгоды | B4: 1 | D4: 1 | F4: 0.5 | H4: 0.5
B5: ROI | C5: NPV, ₸ | D5: ROI | E5: NPV, ₸ | F5: ROI | G5: NPV, ₸ | H5: ROI | I5: NPV, ₸
A6: В0. Ничего не делать (Excel + почта) | B6: =IF(TCO!G7=0,"—",($B$4*TCO!G8-$B$3*TCO!G7)/($B$3*TCO!G7)) | C6: =$B$4*SUMPRODUCT(TCO!C8:F8,df_row)-$B$3*SUMPRODUCT(TCO!C7:F7,df_row) | D6: =IF(TCO!G7=0,"—",($D$4*TCO!G8-$D$3*TCO!G7)/($D$3*TCO!G7)) | E6: =$D$4*SUMPRODUCT(TCO!C8:F8,df_row)-$D$3*SUMPRODUCT(TCO!C7:F7,df_row) | F6: =IF(TCO!G7=0,"—",($F$4*TCO!G8-$F$3*TCO!G7)/($F$3*TCO!G7)) | G6: =$F$4*SUMPRODUCT(TCO!C8:F8,df_row)-$F$3*SUMPRODUCT(TCO!C7:F7,df_row) | H6: =IF(TCO!G7=0,"—",($H$4*TCO!G8-$H$3*TCO!G7)/($H$3*TCO!G7)) | I6: =$H$4*SUMPRODUCT(TCO!C8:F8,df_row)-$H$3*SUMPRODUCT(TCO!C7:F7,df_row)
A7: В1. Купить готовое: Битрикс24 «Стандартный» | B7: =IF(TCO!G19=0,"—",($B$4*TCO!G20-$B$3*TCO!G19)/($B$3*TCO!G19)) | C7: =$B$4*SUMPRODUCT(TCO!C20:F20,df_row)-$B$3*SUMPRODUCT(TCO!C19:F19,df_row) | D7: =IF(TCO!G19=0,"—",($D$4*TCO!G20-$D$3*TCO!G19)/($D$3*TCO!G19)) | E7: =$D$4*SUMPRODUCT(TCO!C20:F20,df_row)-$D$3*SUMPRODUCT(TCO!C19:F19,df_row) | F7: =IF(TCO!G19=0,"—",($F$4*TCO!G20-$F$3*TCO!G19)/($F$3*TCO!G19)) | G7: =$F$4*SUMPRODUCT(TCO!C20:F20,df_row)-$F$3*SUMPRODUCT(TCO!C19:F19,df_row) | H7: =IF(TCO!G19=0,"—",($H$4*TCO!G20-$H$3*TCO!G19)/($H$3*TCO!G19)) | I7: =$H$4*SUMPRODUCT(TCO!C20:F20,df_row)-$H$3*SUMPRODUCT(TCO!C19:F19,df_row)
A8: В2. Своя разработка, проприетарный стек (Windows Server + SQL Server) | B8: =IF(TCO!G32=0,"—",($B$4*TCO!G33-$B$3*TCO!G32)/($B$3*TCO!G32)) | C8: =$B$4*SUMPRODUCT(TCO!C33:F33,df_row)-$B$3*SUMPRODUCT(TCO!C32:F32,df_row) | D8: =IF(TCO!G32=0,"—",($D$4*TCO!G33-$D$3*TCO!G32)/($D$3*TCO!G32)) | E8: =$D$4*SUMPRODUCT(TCO!C33:F33,df_row)-$D$3*SUMPRODUCT(TCO!C32:F32,df_row) | F8: =IF(TCO!G32=0,"—",($F$4*TCO!G33-$F$3*TCO!G32)/($F$3*TCO!G32)) | G8: =$F$4*SUMPRODUCT(TCO!C33:F33,df_row)-$F$3*SUMPRODUCT(TCO!C32:F32,df_row) | H8: =IF(TCO!G32=0,"—",($H$4*TCO!G33-$H$3*TCO!G32)/($H$3*TCO!G32)) | I8: =$H$4*SUMPRODUCT(TCO!C33:F33,df_row)-$H$3*SUMPRODUCT(TCO!C32:F32,df_row)
A9: В3. Своя разработка, открытый стек (Linux + PostgreSQL + Python) | B9: =IF(TCO!G44=0,"—",($B$4*TCO!G45-$B$3*TCO!G44)/($B$3*TCO!G44)) | C9: =$B$4*SUMPRODUCT(TCO!C45:F45,df_row)-$B$3*SUMPRODUCT(TCO!C44:F44,df_row) | D9: =IF(TCO!G44=0,"—",($D$4*TCO!G45-$D$3*TCO!G44)/($D$3*TCO!G44)) | E9: =$D$4*SUMPRODUCT(TCO!C45:F45,df_row)-$D$3*SUMPRODUCT(TCO!C44:F44,df_row) | F9: =IF(TCO!G44=0,"—",($F$4*TCO!G45-$F$3*TCO!G44)/($F$3*TCO!G44)) | G9: =$F$4*SUMPRODUCT(TCO!C45:F45,df_row)-$F$3*SUMPRODUCT(TCO!C44:F44,df_row) | H9: =IF(TCO!G44=0,"—",($H$4*TCO!G45-$H$3*TCO!G44)/($H$3*TCO!G44)) | I9: =$H$4*SUMPRODUCT(TCO!C45:F45,df_row)-$H$3*SUMPRODUCT(TCO!C44:F44,df_row)
A10: В3-С. Открытый стек силами студенческой команды (рекомендуется) | B10: =IF(TCO!G56=0,"—",($B$4*TCO!G57-$B$3*TCO!G56)/($B$3*TCO!G56)) | C10: =$B$4*SUMPRODUCT(TCO!C57:F57,df_row)-$B$3*SUMPRODUCT(TCO!C56:F56,df_row) | D10: =IF(TCO!G56=0,"—",($D$4*TCO!G57-$D$3*TCO!G56)/($D$3*TCO!G56)) | E10: =$D$4*SUMPRODUCT(TCO!C57:F57,df_row)-$D$3*SUMPRODUCT(TCO!C56:F56,df_row) | F10: =IF(TCO!G56=0,"—",($F$4*TCO!G57-$F$3*TCO!G56)/($F$3*TCO!G56)) | G10: =$F$4*SUMPRODUCT(TCO!C57:F57,df_row)-$F$3*SUMPRODUCT(TCO!C56:F56,df_row) | H10: =IF(TCO!G56=0,"—",($H$4*TCO!G57-$H$3*TCO!G56)/($H$3*TCO!G56)) | I10: =$H$4*SUMPRODUCT(TCO!C57:F57,df_row)-$H$3*SUMPRODUCT(TCO!C56:F56,df_row)
A12: Точка безубыточности для В3-С: при каком множителе выгоды NPV = 0 (при базовых затратах) | B12: =SUMPRODUCT(TCO!C56:F56,df_row)/SUMPRODUCT(TCO!C57:F57,df_row)

Sheet Параметры
A1: Параметры модели. Жёлтые ячейки можно менять — пересчитаются все листы.
A3: Ключ | B3: Параметр | C3: Значение | D3: Ед. | E3: Источник / допущение
A4: usd_kzt | B4: Курс USD/KZT | C4: 445.65 | D4: ₸ | E4: S6
A5: discount_rate | B5: Ставка дисконтирования (базовая ставка НБ РК) | C5: 0.1625 | D5: % | E5: S7
A6: vat | B6: НДС | C6: 0.16 | D6: % | E6: S8
A7: salary_edu | B7: Средняя зарплата в образовании (методист, куратор) | C7: 315100 | D7: ₸/мес | E7: S1
A8: salary_dev | B8: Средняя зарплата Junior Python-разработчика | C8: 468000 | D8: ₸/мес | E8: S2
A9: payroll_factor | B9: Коэффициент начислений на ФОТ | C9: 1.15 | D9: × | E9: A1
A10: hours_month | B10: Рабочих часов в месяце | C10: 168 | D10: ч | E10: A2
A11: methodist_h_before | B11: Методист: сведение заявок сейчас | C11: 4 | D11: ч/нед | E11: A3
A12: methodist_h_after | B12: Методист: сведение заявок после внедрения | C12: 1 | D12: ч/нед | E12: A3
A13: active_weeks | B13: Недель в году с потоком заявок | C13: 36 | D13: нед | E13: A4
A14: curators | B14: Количество кураторов практики | C14: 12 | D14: чел | E14: A5
A15: curator_h_week | B15: Куратор: выяснение статусов и сроков | C15: 0.5 | D15: ч/нед | E15: A5
... A38: b24_decommission_hours | B38: Выгрузка данных из Битрикс24 | C38: 8 | D38: ч | E38: A12

Sheet Эффект
A1: Ставки и годовой эффект (формулы видны в ячейках столбца B)
A3: Стоимость часа методиста/куратора, ₸ | B3: =salary_edu*payroll_factor/hours_month
A4: Стоимость часа разработчика, ₸ | B4: =salary_dev*payroll_factor/hours_month
A5: Сэкономлено часов методиста в год | B5: =(methodist_h_before-methodist_h_after)*active_weeks
A6: Сэкономлено часов кураторов в год | B6: =curators*curator_h_week*curator_saving*curator_weeks
A7: Часы на разбор потерянных заявок в год | B7: =lost_cases_year*lost_case_hours
A8: Итого сэкономлено часов в год | B8: =h_methodist+h_curators+h_lost
A9: Годовой эффект при 100 % реализации, ₸ | B9: =h_total*rate_edu
A10: Cost of delay: потеря в месяц без системы, ₸ | B10: =annual_benefit/12
A12: Не монетизировано: прослеживаемый статус заявки (0 → 100 %), снижение риска по закону РК о персональных данных (заявки с ПДн сейчас лежат в почте и Excel), время студентов.

Sheet TCO
A1: TCO на 3 года по вариантам, ₸. Год 0 — внедрение (4 месяца), годы 1–3 — эксплуатация.
A3: Вариант / статья | C3: Год 0 (внедрение) | D3: Год 1 | E3: Год 2 | F3: Год 3 | G3: Итого
B4: Коэф. дисконтирования | C4: =1/(1+discount_rate)^0 | D4: =1/(1+discount_rate)^1 | E4: =1/(1+discount_rate)^2 | F4: =1/(1+discount_rate)^3
A6: В0. Ничего не делать (Excel + почта)
A7: Итого затраты | C7: 0 | D7: 0 | E7: 0 | F7: 0 | G7: 0
A8: Выгода (экономия времени персонала) | C8: =annual_benefit*0*0 | D8: =annual_benefit*0*ramp_y1 | E8: =annual_benefit*0*1 | F8: =annual_benefit*0*1 | G8: =SUM(C8:F8)
A9: Чистый денежный поток | C9: =C8-C7 | D9: =D8-D7 | E9: =E8-E7 | F9: =F8-F7 | G9: =G8-G7
A10: Накопленный поток | C10: =C9 | D10: =C10+D9 | E10: =D10+E9 | F10: =E10+F9
A12: В1. Купить готовое: Битрикс24 «Стандартный»
A13: Подписка Битрикс24 «Стандартный» (с НДС) | C13: =b24_month*12*(1+vat)/3 | D13: =b24_month*12*(1+vat) | E13: =b24_month*12*(1+vat) | F13: =b24_month*12*(1+vat) | G13: =SUM(C13:F13)
A14: Настройка портала | C14: =b24_setup_hours*rate_dev | D14: 0 | E14: 0 | F14: 0 | G14: =SUM(C14:F14)
A15: Перенос данных из Excel | C15: =migration_hours*rate_dev | D15: 0 | E15: 0 | F15: 0 | G15: =SUM(C15:F15)
A16: Обучение персонала | C16: =users_trained*training_h_user*rate_edu | D16: =retraining_h_year*rate_edu | E16: =retraining_h_year*rate_edu | F16: =retraining_h_year*rate_edu | G16: =SUM(C16:F16)
A17: Администрирование | C17: 0 | D17: =b24_support_h_month*12*rate_dev | E17: =b24_support_h_month*12*rate_dev | F17: =b24_support_h_month*12*rate_dev | G17: =SUM(C17:F17)
A18: Выгрузка данных при отказе | C18: 0 | D18: 0 | E18: 0 | F18: =b24_decommission_hours*rate_dev | G18: =SUM(C18:F18)
A19: Итого затраты | C19: =SUM(C13:C18) | D19: =SUM(D13:D18) | E19: =SUM(E13:E18) | F19: =SUM(F13:F18) | G19: =SUM(G13:G18)
A20: Выгода (экономия времени персонала) | C20: =annual_benefit*b24_benefit_share*0 | D20: =annual_benefit*b24_benefit_share*ramp_y1 | E20: =annual_benefit*b24_benefit_share*1 | F20: =annual_benefit*b24_benefit_share*1 | G20: =SUM(C20:F20)
A21: Чистый денежный поток | C21: =C20-C19 | D21: =D20-D19 | E21: =E20-E19 | F21: =F20-F19 | G21: =G20-G19
A22: Накопленный поток | C22: =C21 | D22: =C22+D21 | E22: =D22+E21 | F22: =E22+F21
A24: В2. Своя разработка, проприетарный стек (Windows Server + SQL Server)
A25: Разработка MVP | C25: =(dev_hours+pm_ba_hours)*rate_dev | D25: 0 | E25: 0 | F25: 0 | G25: =SUM(C25:F25)
A26: Лицензии Windows Server + SQL Server (с НДС) | C26: =(ws_license_usd+sql_2core_usd*sql_packs)*usd_kzt*(1+vat) | D26: 0 | E26: 0 | F26: 0 | G26: =SUM(C26:F26)
A27: Инфраструктура: VPS + резервные копии | C27: =(vps_month+backup_vps_month)*12/3 | D27: =(vps_month+backup_vps_month)*12 | E27: =(vps_month+backup_vps_month)*12 | F27: =(vps_month+backup_vps_month)*12 | G27: =SUM(C27:F27)
A28: Перенос данных из Excel | C28: =migration_hours*rate_dev | D28: 0 | E28: 0 | F28: 0 | G28: =SUM(C28:F28)
A29: Обучение персонала | C29: =users_trained*training_h_user*rate_edu | D29: =retraining_h_year*rate_edu | E29: =retraining_h_year*rate_edu | F29: =retraining_h_year*rate_edu | G29: =SUM(C29:F29)
A30: Поддержка и сопровождение | C30: 0 | D30: =support_h_month*12*rate_dev | E30: =support_h_month*12*rate_dev | F30: =support_h_month*12*rate_dev | G30: =SUM(C30:F30)
A31: Вывод из эксплуатации | C31: 0 | D31: 0 | E31: 0 | F31: =decommission_hours*rate_dev | G31: =SUM(C31:F31)
A32: Итого затраты | C32: =SUM(C25:C31) | D32: =SUM(D25:D31) | E32: =SUM(E25:E31) | F32: =SUM(F25:F31) | G32: =SUM(G25:G31)
A33: Выгода (экономия времени персонала) | C33: =annual_benefit*1*0 | D33: =annual_benefit*1*ramp_y1 | E33: =annual_benefit*1*1 | F33: =annual_benefit*1*1 | G33: =SUM(C33:F33)
A34: Чистый денежный поток | C34: =C33-C32 | D34: =D33-D32 | E34: =E33-E32 | F34: =F33-F32 | G34: =G33-G32
A35: Накопленный поток | C35: =C34 | D35: =C35+D34 | E35: =D35+E34 | F35: =E35+F34
A37: В3. Своя разработка, открытый стек (Linux + PostgreSQL + Python)
A38: Разработка MVP | C38: =(dev_hours+pm_ba_hours)*rate_dev | D38: 0 | E38: 0 | F38: 0 | G38: =SUM(C38:F38)
A39: Инфраструктура: VPS + резервные копии | C39: =(vps_month+backup_vps_month)*12/3 | D39: =(vps_month+backup_vps_month)*12 | E39: =(vps_month+backup_vps_month)*12 | F39: =(vps_month+backup_vps_month)*12 | G39: =SUM(C39:F39)
A40: Перенос данных из Excel | C40: =migration_hours*rate_dev | D40: 0 | E40: 0 | F40: 0 | G40: =SUM(C40:F40)
A41: Обучение персонала | C41: =users_trained*training_h_user*rate_edu | D41: =retraining_h_year*rate_edu | E41: =retraining_h_year*rate_edu | F41: =retraining_h_year*rate_edu | G41: =SUM(C41:F41)
A42: Поддержка и сопровождение | C42: 0 | D42: =support_h_month*12*rate_dev | E42: =support_h_month*12*rate_dev | F42: =support_h_month*12*rate_dev | G42: =SUM(C42:F42)
A43: Вывод из эксплуатации | C43: 0 | D43: 0 | E43: 0 | F43: =decommission_hours*rate_dev | G43: =SUM(C43:F43)
A44: Итого затраты | C44: =SUM(C38:C43) | D44: =SUM(D38:D43) | E44: =SUM(E38:E43) | F44: =SUM(F38:F43) | G44: =SUM(G38:G43)
A45: Выгода (экономия времени персонала) | C45: =annual_benefit*1*0 | D45: =annual_benefit*1*ramp_y1 | E45: =annual_benefit*1*1 | F45: =annual_benefit*1*1 | G45: =SUM(C45:F45)
...

Sheet Источники и допущения
A1: ID | B1: Источник (открытый, дата обращения 24.09.2026) / допущение
A2: S1 | B2: Бюро национальной статистики АСПиР РК. Заработная плата за I квартал 2026 года — stat.gov.kz/ru/news/zarabotnaya-plata-za-i-kvartal-2026-goda/
A3: S2 | B3: Taylor.kz. Зарплата Python-разработчика в Казахстане 2026 (Junior — среднее 468 000 ₸) — taylor.kz/salaries/python
A4: S3 | B4: Hoster.kz. Облачные серверы, прайс — hoster.kz/cloud/vps/
A5: S4 | B5: Битрикс24 Казахстан. Тарифы и цены (без НДС) — bitrix24.kz/prices/
A6: S5 | B6: Microsoft. SQL Server 2025 Pricing (PDF, $3 945 за 2 ядра Standard); Microsoft Store: Windows Server 2025 Standard 16 core ($1 176) — microsoft.com
A7: S6 | B7: Национальный Банк РК. Официальный курс USD/KZT на 24.09.2026 = 445,65 ₸ — nationalbank.kz
A8: S7 | B8: Национальный Банк РК. О снижении базовой ставки до 16,25 % (04.09.2026) — nationalbank.kz/ru/news/press-relizy/20266
A9: S8 | B9: Налоговый кодекс РК (действует с 01.01.2026): ставка НДС 16 % — adilet.zan.kz
A10: A1 | B10: Начисления работодателя на ФОТ — коэффициент 1,15 (социальный налог и взносы, укрупнённо).
A11: A2 | B11: 168 рабочих часов в месяце (40 ч × 4,2 недели).
A12: A3 | B12: Методист сейчас тратит 4 ч/нед на сведение заявок, после внедрения — 1 ч/нед (карточка проекта ЛЗ 1; подтвердить у заказчика).
... A26: A17 | B26: Нагрузка 30–40 заявок в неделю и до 15 сотрудников: сервера 1 vCPU / 2 ГБ достаточно для FastAPI + PostgreSQL (проверить нагрузочным тестом в ЗС 11).
